Workbook

Sheet 00_Inicio
A1: Excel básico — guía paso a paso con práctica
A3: Recorré las hojas en orden. Leé la explicación, observá el ejemplo verde y completá las celdas amarillas.
A5: Color | B5: Significado | D5: Cómo usar este archivo
A6: Azul claro | B6: Explicación o pasos | D6: 1) Empezá por la hoja 01_Interfaz_Celdas. 2) No borres los ejemplos verdes: usalos como referencia. 3) Escribí solamente en las celdas amarillas. 4) En 08_Soluciones podés comprobar fórmulas y resultados. 5) Guardá una copia antes de practicar para poder reiniciar.
A7: Verde | B7: Ejemplo resuelto
A8: Amarillo | B8: Celda para practicar
A9: Gris | B9: Consejo o referencia
A11: Recorrido recomendado
A12: Orden | B12: Hoja | C12: Tema | D12: Objetivo práctico | E12: Estado
A13: 1 | B13: 01_Interfaz_Celdas | C13: Interfaz, celdas y autorrelleno | D13: Ingresar, editar y completar series | E13: Pendiente
A14: 2 | B14: 02_Copiar_Pegar | C14: Copiar, pegar especial y diseño | D14: Distinguir valores, fórmulas y formatos | E14: Pendiente
A15: 3 | B15: 03_Listas_Datos | C15: Filtros, orden, búsqueda e inmovilización | D15: Trabajar con una lista extensa | E15: Pendiente
A16: 4 | B16: 04_Formulas | C16: Fórmulas manuales y funciones básicas | D16: Escribir y copiar fórmulas | E16: Pendiente
A17: 5 | B17: 05_Referencias | C17: Referencias relativas y absolutas | D17: Usar el símbolo $ correctamente | E17: Pendiente
A18: 6 | B18: 06_Impresion_PDF | C18: Área de impresión y exportación PDF | D18: Evitar tablas cortadas | E18: Pendiente
A19: 7 | B19: 07_Practica_Final | C19: Ejercicio integrador | D19: Aplicar todos los temas | E19: Pendiente
A21: Atajos esenciales
A22: Acción | B22: Atajo | C22: Uso
A23: Copiar | B23: Ctrl + C | C23: Copia el contenido seleccionado.
A24: Pegar | B24: Ctrl + V | C24: Pega el contenido copiado.
A25: Deshacer | B25: Ctrl + Z | C25: Revierte la última acción.
A26: Buscar | B26: Ctrl + B | C26: Abre Buscar en Excel en español.
A27: Reemplazar | B27: Ctrl + L | C27: Abre Buscar y reemplazar en Excel en español.
A28: Relleno rápido | B28: Ctrl + E | C28: Detecta un patrón y completa datos.
A29: Guardar | B29: Ctrl + G | C29: Guarda el archivo en Excel en español.
A30: Alternar referencia | B30: F4 | C30: Agrega o cambia los símbolos $ en una fórmula.

Sheet 01_Interfaz_Celdas
A1: 1. Interfaz de Excel, celdas y autorrelleno
A3: Objetivo: reconocer las partes de Excel, ingresar distintos tipos de datos, ajustar columnas y completar patrones.
A5: Partes principales de la interfaz
A6: Elemento | B6: Dónde está | C6: Para qué sirve
A7: Cinta de opciones | B7: Parte superior | C7: Agrupa herramientas en pestañas: Inicio, Insertar, Diseño de página, Fórmulas, Datos, Revisar y Vista.
A8: Barra de acceso rápido | B8: Esquina superior izquierda | C8: Accesos a Guardar, Deshacer y Rehacer. Se puede personalizar.
A9: Cuadro de nombres | B9: A la izquierda de la barra de fórmulas | C9: Muestra la celda activa (por ejemplo A1) y permite ir directamente a una celda o rango.
A10: Barra de fórmulas | B10: Debajo de la cinta | C10: Muestra y permite editar el contenido completo de la celda activa.
A11: Encabezados de filas y columnas | B11: Letras arriba y números a la izquierda | C11: Permiten identificar y seleccionar filas, columnas y celdas.
A12: Pestañas de hojas | B12: Parte inferior | C12: Cambian entre hojas, permiten crear, mover, copiar, renombrar o eliminar hojas.
A13: Barra de estado | B13: Parte inferior | C13: Muestra suma, promedio y recuento de una selección, además del zoom y las vistas.
A14: Barras de desplazamiento | B14: Derecha e inferior | C14: Permiten recorrer zonas de la hoja que no están visibles.
A16: Ingresar y editar datos
A17: Paso | B17: Qué hacer
A18: 1. Seleccionar una celda | B18: Hacé clic sobre la celda. El borde indica cuál está activa.
A19: 2. Ingresar contenido | B19: Escribí texto, números o fechas y presioná Enter. Usá Tab para pasar a la celda de la derecha.
A20: 3. Editar | B20: Hacé doble clic en la celda o seleccionála y editá desde la barra de fórmulas.
A21: 4. Borrar | B21: Presioná Supr para quitar el contenido sin eliminar el formato.
A22: 5. Ajustar columnas | B22: Ubicá el cursor entre dos letras de columna. Arrastrá o hacé doble clic para autoajustar.
A24: Tipo de dato | B24: Ejemplo | C24: Cómo lo interpreta Excel | D24: Practicá aquí | E24: Resultado esperado | F24: Consejo
A25: Texto | B25: Producto A | C25: Etiqueta o descripción | D25: Escribí un texto | E25: Texto alineado normalmente a la izquierda | F25: Para conservar ceros iniciales, usá formato Texto.
A26: Número | B26: 1250.5 | C26: Valor que puede calcularse | D26: 2500 | E26: Número alineado normalmente a la derecha | F26: No escribas el símbolo de moneda dentro del valor.
A27: Porcentaje | B27: 0.15 | C27: Valor decimal mostrado como porcentaje | D27: 0.25 | E27: 15% | F27: Podés escribir 15% directamente.
A28: Fecha | B28: 46222 | C28: Número de serie con formato fecha | D28: 46235 | E28: 19/07/2026 | F28: Las fechas se pueden ordenar y restar.
A29: Código como texto | B29: 00125 | C29: Texto que conserva ceros | D29: 00077 | E29: 00125 | F29: Aplicá formato Texto antes de escribir.
A31: Autorrelleno: series y Relleno rápido
A32: Controlador de relleno: seleccioná las primeras celdas del patrón y arrastrá el pequeño cuadrado de la esquina inferior derecha. Relleno rápido (Ctrl + E): escribí uno o dos ejemplos del resultado deseado y Excel detectará el patrón.
A35: Serie | B35: Inicio 1 | C35: Inicio 2 | D35: Continuar aquí | G35: Resultado esperado | J35: Acción
A36: Números | B36: 1 | C36: 2 | G36: 3, 4, 5, 6 | J36: Seleccioná B36:C36 y arrastrá hasta F36.
A37: Días | B37: lunes | C37: martes | G37: miércoles a sábado | J37: Seleccioná B37:C37 y arrastrá hasta F37.
A38: Fechas | B38: 46204 | C38: 46205 | G38: 03/07/2026 a 06/07/2026 | J38: Seleccioná B38:C38 y arrastrá hasta F38.
A40: Nombre completo | B40: Nombre extraído | C40: Apellido extraído | D40: Instrucción
A41: Ana Torres | B41: Ana | C41: Torres | D41: Ejemplo inicial
A42: Carlos Gómez | D42: Escribí Carlos en B42, Gómez en C42 y luego usá Ctrl + E hacia abajo.
A43: Lucía Pérez
A44: Martín López
A45: Sofía Díaz

Sheet 02_Copiar_Pegar
A1: 2. Copiar, pegar especial y diseño visual
A3: Objetivo: copiar contenido sin errores, elegir qué parte pegar y aplicar formatos profesionales a una tabla.
A5: Copiar y pegar: pasos esenciales
A6: Paso | B6: Qué hacer
A7: 1. Seleccionar | B7: Marcá la celda o rango que querés copiar.
A8: 2. Copiar | B8: Presioná Ctrl + C. Verás un borde móvil alrededor de la selección.
A9: 3. Elegir destino | B9: Hacé clic en la primera celda donde querés colocar la copia.
A10: 4. Pegar | B10: Presioná Ctrl + V para pegar contenido, fórmulas y formato.
A11: 5. Pegar especial | B11: Usá Inicio > Pegar > Pegado especial para decidir si querés valores, fórmulas, formatos, transponer o realizar una operación.
A13: Ejemplo: diferencia entre fórmulas y valores
A14: Producto | B14: Cantidad | C14: Precio | D14: Total | E14: Fórmula visible | H14: Pegado como valores | I14: Cantidad | J14: Precio | K14: Total fijo | L14: Qué ocurre
A15: Teclado | B15: 2 | C15: 18500 | D15: =B15*C15 -> 37000 | E15: =B15*C15 | H15: Teclado | I15: 2 | J15: 18500 | K15: 37000 | L15: El número no cambia aunque se modifique el origen.
A16: Mouse | B16: 4 | C16: 8200 | D16: =B16*C16 -> 32800 | E16: =B16*C16 | H16: Mouse | I16: 4 | J16: 8200 | K16: 32800 | L16: El número no cambia aunque se modifique el origen.
A17: Auriculares | B17: 3 | C17: 23500 | D17: =B17*C17 -> 70500 | E17: =B17*C17 | H17: Auriculares | I17: 3 | J17: 23500 | K17: 70500 | L17: El número no cambia aunque se modifique el origen.
A18: Webcam | B18: 1 | C18: 41000 | D18: =B18*C18 -> 41000 | E18: =B18*C18 | H18: Webcam | I18: 1 | J18: 41000 | K18: 41000 | L18: El número no cambia aunque se modifique el origen.
A20: Opciones de Pegado especial
A21: Opción | B21: Qué pega | C21: Cuándo usarla
A22: Valores | B22: Solo el resultado visible | C22: Para quitar fórmulas y conservar los resultados.
A23: Fórmulas | B23: Solo las fórmulas | C23: Para copiar cálculos sin copiar colores ni bordes.
A24: Formatos | B24: Solo diseño | C24: Para repetir moneda, bordes, colores y alineación.
A25: Transponer | B25: Cambia filas por columnas | C25: Para girar una tabla horizontal a vertical o viceversa.
A26: Multiplicar / sumar | B26: Aplica una operación al destino | C26: Para aumentar precios o ajustar datos sin crear una fórmula auxiliar.
A28: Práctica de Pegado especial: aumentar precios un 10%
A29: Producto | B29: Precio original | C29: Factor | D29: Precio a modificar | E29: Pasos
A30: Cuaderno | B30: 4500 | C30: 1.1 | D30: 4500 | E30: Copiá C30. Seleccioná D30:D34. Pegado especial > Multiplicar.
A31: Lapicera | B31: 1200 | D31: 1200
A32: Mochila | B32: 28500 | D32: 28500
A33: Regla | B33: 950 | D33: 950
A34: Calculadora | B34: 17800 | D34: 17800
A36: Diseño visual de tablas
A37: Tabla sin formato | B37: Importe | C37: Margen | D37: Estado | E37: Fecha | H37: Tabla con diseño profesional | I37: Importe | J37: Margen | K37: Estado | L37: Fecha
A38: Venta 001 | B38: 125000 | C38: 0.18 | D38: Pagada | E38: 46204 | H38: Venta 001 | I38: 125000 | J38: 0.18 | K38: Pagada | L38: 46204
A39: Venta 002 | B39: 89500 | C39: 0.12 | D39: Pendiente | E39: 46206 | H39: Venta 002 | I39: 89500 | J39: 0.12 | K39: Pendiente | L39: 46206
A40: Venta 003 | B40: 210000 | C40: 0.25 | D40: Pagada | E40: 46210 | H40: Venta 003 | I40: 210000 | J40: 0.25 | K40: Pagada | L40: 46210
A41: Venta 004 | B41: 45500 | C41: 0.08 | D41: Cancelada | E41: 46212 | H41: Venta 004 | I41: 45500 | J41: 0.08 | K41: Cancelada | L41: 46212
A42: Venta 005 | B42: 173000 | C42: 0.2 | D42: Pagada | E42: 46213 | H42: Venta 005 | I42: 173000 | J42: 0.2 | K42: Pagada | L42: 46213
A44: Práctica: aplicá a la tabla de la izquierda un encabezado destacado, formato moneda en Importe, porcentaje en Margen, fecha dd/mm/aaaa, bordes finos y alineación coherente. Usá Copiar formato o Pegado especial > Formatos si querés replicar el diseño de la derecha.

Sheet 03_Listas_Datos
A1: 3. Manejo de listas: filtros, orden, búsqueda e inmovilización
A3: Objetivo: trabajar con una lista extensa sin perder los encabezados y encontrar rápidamente la información necesaria.
A5: Practicá sobre la tabla: 1) filtrá Estado = Pendiente; 2) ordená Vendedor de A a Z; 3) ordená Total de mayor a menor; 4) buscá “Córdoba” y reemplazalo por “Córdoba Capital”; 5) hacé scroll y comprobá que el encabezado permanece visible.
A7: ID | B7: Fecha | C7: Vendedor | D7: Provincia | E7: Categoría | F7: Unidades | G7: Precio unitario | H7: Total | I7: Estado
A8: 1001 | B8: 46174 | C8: Ana | D8: Buenos Aires | E8: Tecnología | F8: 1 | G8: 3500 | H8: =F8*G8 -> 3500 | I8: Entregado
A9: 1002 | B9: 46175 | C9: Bruno | D9: Santa Fe | E9: Accesorios | F9: 4 | G9: 11400 | H9: =F9*G9 -> 45600 | I9: Entregado
A10: 1003 | B10: 46176 | C10: Carla | D10: Tucumán | E10: Hogar | F10: 7 | G10: 19300 | H10: =F10*G10 -> 135100 | I10: Pendiente
A11: 1004 | B11: 46177 | C11: Diego | D11: Córdoba | E11: Oficina | F11: 10 | G11: 27200 | H11: =F11*G11 -> 272000 | I11: Pendiente
A12: 1005 | B12: 46178 | C12: Elena | D12: Mendoza | E12: Tecnología | F12: 1 | G12: 35100 | H12: =F12*G12 -> 35100 | I12: Cancelado
A13: 1006 | B13: 46179 | C13: Federico | D13: Buenos Aires | E13: Accesorios | F13: 4 | G13: 43000 | H13: =F13*G13 -> 172000 | I13: Entregado
A14: 1007 | B14: 46180 | C14: Ana | D14: Santa Fe | E14: Hogar | F14: 7 | G14: 50900 | H14: =F14*G14 -> 356300 | I14: Entregado
A15: 1008 | B15: 46181 | C15: Bruno | D15: Tucumán | E15: Oficina | F15: 10 | G15: 6800 | H15: =F15*G15 -> 68000 | I15: Pendiente
A16: 1009 | B16: 46182 | C16: Carla | D16: Córdoba | E16: Tecnología | F16: 1 | G16: 14700 | H16: =F16*G16 -> 14700 | I16: Pendiente
A17: 1010 | B17: 46183 | C17: Diego | D17: Mendoza | E17: Accesorios | F17: 4 | G17: 22600 | H17: =F17*G17 -> 90400 | I17: Cancelado
A18: 1011 | B18: 46184 | C18: Elena | D18: Buenos Aires | E18: Hogar | F18: 7 | G18: 30500 | H18: =F18*G18 -> 213500 | I18: Entregado
A19: 1012 | B19: 46185 | C19: Federico | D19: Santa Fe | E19: Oficina | F19: 10 | G19: 38400 | H19: =F19*G19 -> 384000 | I19: Entregado
... A37: 1030 | B37: 46203 | C37: Federico | D37: Mendoza | E37: Accesorios | F37: 4 | G37: 24600 | H37: =F37*G37 -> 98400 | I37: Cancelado
A39: Cómo usar cada herramienta
A40: Herramienta | B40: Ruta y pasos
A41: Filtro | B41: Seleccioná una celda de la lista > Datos > Filtro. Usá la flecha del encabezado para marcar valores o aplicar condiciones.
A42: Ordenar A a Z | B42: Abrí la flecha del encabezado de texto > Ordenar de A a Z. Para números, elegí de menor a mayor o de mayor a menor.
A43: Buscar y reemplazar | B43: Ctrl + B para buscar. Ctrl + L para reemplazar. Revisá las opciones para buscar en la hoja o en todo el libro.
A44: Inmovilizar títulos | B44: Vista > Inmovilizar > Inmovilizar paneles. Primero seleccioná la celda debajo y a la derecha de lo que querés mantener fijo.

Sheet 04_Formulas
A1: 4. Fórmulas manuales y funciones obligatorias
A3: Objetivo: entender cómo comienza una fórmula, usar operadores y aplicar SUMA, PROMEDIO, CONTAR, MAX y MIN.
A5: Anatomía de una fórmula | H5: Funciones básicas
A6: Concepto | B6: Ejemplo | C6: Explicación | H6: Función | I6: Fórmula en Excel español | J6: Resultado | K6: Qué devuelve
A7: Signo igual | B7: =B2+C2 | C7: Toda fórmula comienza con =. | H7: SUMA | I7: =SUMA(B14:E18) | J7: =SUM(B14:E18) -> 2933 | K7: Suma todos los valores.
A8: Referencias | B8: =B2*C2 | C8: B2 y C2 indican las celdas utilizadas. | H8: PROMEDIO | I8: =PROMEDIO(B14:E18) | J8: =AVERAGE(B14:E18) -> 146.65 | K8: Calcula la media aritmética.
A9: Operadores | B9: + - * / ^ | C9: Suma, resta, multiplicación, división y potencia. | H9: CONTAR | I9: =CONTAR(B14:E18) | J9: =COUNT(B14:E18) -> 20 | K9: Cuenta celdas que contienen números.
A10: Paréntesis | B10: =(B2+C2)*D2 | C10: Controlan qué operación se realiza primero. | H10: MAX | I10: =MAX(B14:E18) | J10: =MAX(B14:E18) -> 245 | K10: Devuelve el número más alto.
H11: MIN | I11: =MIN(B14:E18) | J11: =MIN(B14:E18) -> 75 | K11: Devuelve el número más bajo.
A12: Ejemplo de cálculo manual
A13: Producto | B13: Enero | C13: Febrero | D13: Marzo | E13: Abril | F13: Total por producto
A14: Producto A | B14: 120 | C14: 135 | D14: 150 | E14: 170 | F14: =B14+C14+D14+E14 -> 575
A15: Producto B | B15: 95 | C15: 110 | D15: 100 | E15: 125 | F15: =B15+C15+D15+E15 -> 430
A16: Producto C | B16: 210 | C16: 190 | D16: 230 | E16: 245 | F16: =B16+C16+D16+E16 -> 875
A17: Producto D | B17: 75 | C17: 90 | D17: 88 | E17: 105 | F17: =B17+C17+D17+E17 -> 358
A18: Producto E | B18: 160 | C18: 155 | D18: 180 | E18: 200 | F18: =B18+C18+D18+E18 -> 695
A21: Práctica: escribí las funciones manualmente
A22: Día | B22: Visitas | C22: Ventas | E22: Cálculo | F22: Fórmula a ingresar | G22: Resultado
A23: Lunes | B23: 120 | C23: 15 | E23: Total de ventas | F23: =SUMA(C23:C29)
A24: Martes | B24: 145 | C24: 18 | E24: Promedio de visitas | F24: =PROMEDIO(B23:B29)
A25: Miércoles | B25: 98 | C25: 11 | E25: Cantidad de días con datos | F25: =CONTAR(C23:C29)
A26: Jueves | B26: 170 | C26: 22 | E26: Mayor cantidad de ventas | F26: =MAX(C23:C29)
A27: Viernes | B27: 155 | C27: 19 | E27: Menor cantidad de ventas | F27: =MIN(C23:C29)
A28: Sábado | B28: 210 | C28: 28
A29: Domingo | B29: 130 | C29: 16
A31: Consejos: escribí las fórmulas sin espacios innecesarios; comprobá que el rango incluya todas las filas; usá el controlador de relleno para copiar una fórmula; y revisá la barra de fórmulas si el resultado no es el esperado.

Sheet 05_Referencias
A1: 5. Referencias relativas y absolutas
A3: Objetivo: copiar fórmulas correctamente y congelar una celda con $ para que no cambie al arrastrar.
A5: Tipos de referencia
A6: Tipo | B6: Ejemplo | C6: Qué cambia al copiar | D6: Uso típico
A7: Relativa | B7: B8 | C7: Cambian fila y columna. | D7: Cálculos que deben adaptarse a cada fila.
A8: Absoluta | B8: $B$4 | C8: No cambia ni fila ni columna. | D8: Impuestos, descuentos, cotizaciones o constantes.
A9: Mixta | B9: $B8 o B$8 | C9: Se congela solo columna o fila. | D9: Tablas de multiplicación y matrices.
A11: Tasa de IVA | B11: Atajo
A12: 0.21 | B12: F4 dentro de la fórmula
A14: Ejemplo resuelto con referencia absoluta | G14: Qué sucede al copiar
A15: Producto | B15: Precio base | C15: Cantidad | D15: Subtotal | E15: Total con IVA | G15: En D16, la fórmula =B16*C16 usa referencias relativas: al copiar hacia abajo se transforma en B17*C17, B18*C18, etc. En E16, la fórmula =D16*(1+$B$11) mantiene fija la tasa de IVA. D16 cambia por fila, pero $B$11 permanece igual.
A16: Monitor | B16: 165000 | C16: 1 | D16: =B16*C16 -> 165000 | E16: =D16*(1+$A$12) -> 199650
A17: Teclado | B17: 28500 | C17: 2 | D17: =B17*C17 -> 57000 | E17: =D17*(1+$A$12) -> 68970
A18: Mouse | B18: 17500 | C18: 3 | D18: =B18*C18 -> 52500 | E18: =D18*(1+$A$12) -> 63525
A19: Auriculares | B19: 55000 | C19: 1 | D19: =B19*C19 -> 55000 | E19: =D19*(1+$A$12) -> 66550
A20: Webcam | B20: 72000 | C20: 2 | D20: =B20*C20 -> 144000 | E20: =D20*(1+$A$12) -> 174240
A23: Práctica: aplicar un descuento fijo
A24: Descuento | B24: 0.1
A25: Fórmula sugerida | B25: =B28*(1-$B$24)
A27: Producto | B27: Precio normal | C27: Precio con descuento | D27: Acción
A28: Silla | B28: 85000 | D28: Ingresá la fórmula en C28 y arrastrá hasta C33.
A29: Escritorio | B29: 145000
A30: Lámpara | B30: 32000
A31: Biblioteca | B31: 99000
A32: Organizador | B32: 18500
A33: Alfombra | B33: 57000
A35: Cómo agregar $: mientras editás una referencia dentro de una fórmula, presioná F4. Cada pulsación alterna entre $B$24, B$24, $B24 y B24.

Sheet 06_Impresion_PDF
A1: 6. Configuración profesional de impresión y PDF
A3: Objetivo: definir qué se imprime, ajustar la tabla a una página de ancho y exportar a PDF sin cortes.
A5: Pasos recomendados
A6: Paso | B6: Qué hacer
A7: 1. Seleccionar la tabla | B7: Marcá el rango completo, incluyendo título y encabezados.
A8: 2. Definir área de impresión | B8: Diseño de página > Área de impresión > Establecer área de impresión.
A9: 3. Elegir orientación | B9: Usá Horizontal cuando la tabla tenga muchas columnas.
A10: 4. Ajustar escala | B10: En Escala para ajustar: Ancho = 1 página y Alto = Automático.
A11: 5. Configurar márgenes | B11: Elegí Márgenes estrechos o personalizados y centrado horizontal si es necesario.
A12: 6. Revisar saltos | B12: Vista > Vista previa de salto de página. Arrastrá las líneas si una columna queda afuera.
A13: 7. Exportar PDF | B13: Archivo > Exportar o Guardar como > PDF. Revisá la vista previa antes de guardar.
A15: Tabla de práctica incluida en el área de impresión
A16: N.º | B16: Fecha | C16: Cliente | D16: Provincia | E16: Producto | F16: Cantidad | G16: Precio | H16: Total
A17: 1 | B17: 46204 | C17: Alfa SRL | D17: Buenos Aires | E17: Notebook | F17: 1 | G17: 950000 | H17: =F17*G17 -> 950000
A18: 2 | B18: 46205 | C18: Beta SA | D18: Córdoba | E18: Monitor | F18: 2 | G18: 180000 | H18: =F18*G18 -> 360000
A19: 3 | B19: 46206 | C19: Gamma SAS | D19: Santa Fe | E19: Impresora | F19: 3 | G19: 265000 | H19: =F19*G19 -> 795000
A20: 4 | B20: 46207 | C20: Delta SRL | D20: Mendoza | E20: Router | F20: 4 | G20: 125000 | H20: =F20*G20 -> 500000
A21: 5 | B21: 46208 | C21: Épsilon SA | D21: Tucumán | E21: Disco SSD | F21: 5 | G21: 145000 | H21: =F21*G21 -> 725000
A22: 6 | B22: 46209 | C22: Alfa SRL | D22: Buenos Aires | E22: Notebook | F22: 1 | G22: 950000 | H22: =F22*G22 -> 950000
A23: 7 | B23: 46210 | C23: Beta SA | D23: Córdoba | E23: Monitor | F23: 2 | G23: 180000 | H23: =F23*G23 -> 360000
A24: 8 | B24: 46211 | C24: Gamma SAS | D24: Santa Fe | E24: Impresora | F24: 3 | G24: 265000 | H24: =F24*G24 -> 795000
A25: 9 | B25: 46212 | C25: Delta SRL | D25: Mendoza | E25: Router | F25: 4 | G25: 125000 | H25: =F25*G25 -> 500000
A26: 10 | B26: 46213 | C26: Épsilon SA | D26: Tucumán | E26: Disco SSD | F26: 5 | G26: 145000 | H26: =F26*G26 -> 725000
A27: 11 | B27: 46214 | C27: Alfa SRL | D27: Buenos Aires | E27: Notebook | F27: 1 | G27: 950000 | H27: =F27*G27 -> 950000
A28: 12 | B28: 46215 | C28: Beta SA | D28: Córdoba | E28: Monitor | F28: 2 | G28: 180000 | H28: =F28*G28 -> 360000
... A40: 24 | B40: 46227 | C40: Delta SRL | D40: Mendoza | E40: Router | F40: 4 | G40: 125000 | H40: =F40*G40 -> 500000
A42: Este archivo ya está configurado para imprimir A1:H40 en orientación horizontal, con márgenes reducidos y ajuste a una página de ancho. Usá esta hoja para comparar la vista previa con tus propias configuraciones.

Sheet 07_Practica_Final
A1: 7. Práctica final integradora
A3: Completá el ejercicio sin mirar la hoja de soluciones. Las celdas amarillas requieren una acción o una fórmula.
A5: Consigna
A6: N.º | B6: Tarea
A7: 1 | B7: Ingresá las fórmulas de Subtotal y Total con IVA; utilizá referencia absoluta para la tasa.
A8: 2 | B8: Copiá las fórmulas hacia abajo con el controlador de relleno.
A9: 3 | B9: Aplicá formato moneda a precios y totales, porcentaje a la tasa y fecha dd/mm/aaaa.
A10: 4 | B10: Activá filtros y ordená Total con IVA de mayor a menor.
A11: 5 | B11: Filtrá la categoría Tecnología y el vendedor Ana.
A12: 6 | B12: Completá el resumen con SUMA, PROMEDIO, CONTAR, MAX y MIN.
A13: 7 | B13: Inmovilizá el encabezado de la tabla y configurá el área de impresión A1:M31.
A15: Tasa de IVA | B15: 0.21
A17: ID | B17: Fecha | C17: Vendedor | D17: Producto | E17: Categoría | F17: Cantidad | G17: Precio unitario | H17: Subtotal | I17: Total con IVA | K17: Resumen | L17: Fórmula sugerida | M17: Resultado
A18: 1 | B18: 46204 | C18: Ana | D18: Notebook | E18: Tecnología | F18: 1 | G18: 880000 | K18: Total general con IVA | L18: =SUMA(I18:I31)
A19: 2 | B19: 46205 | C19: Bruno | D19: Silla | E19: Oficina | F19: 2 | G19: 76000 | K19: Promedio de subtotales | L19: =PROMEDIO(H18:H31)
A20: 3 | B20: 46206 | C20: Carla | D20: Monitor | E20: Tecnología | F20: 2 | G20: 169000 | K20: Cantidad de registros | L20: =CONTAR(A18:A31)
A21: 4 | B21: 46207 | C21: Ana | D21: Mouse | E21: Accesorios | F21: 5 | G21: 18500 | K21: Mayor total con IVA | L21: =MAX(I18:I31)
A22: 5 | B22: 46208 | C22: Diego | D22: Escritorio | E22: Oficina | F22: 1 | G22: 142000 | K22: Menor total con IVA | L22: =MIN(I18:I31)
A23: 6 | B23: 46209 | C23: Elena | D23: Router | E23: Tecnología | F23: 3 | G23: 118000
A24: 7 | B24: 46210 | C24: Ana | D24: Disco SSD | E24: Tecnología | F24: 2 | G24: 145000 | K24: Lista de control | L24: Estado | M24: Cómo comprobar
A25: 8 | B25: 46211 | C25: Bruno | D25: Lámpara | E25: Hogar | F25: 4 | G25: 29500 | K25: Fórmulas copiadas | L25: Pendiente | M25: No deben quedar celdas vacías en H18:I31.
A26: 9 | B26: 46212 | C26: Carla | D26: Teclado | E26: Accesorios | F26: 3 | G26: 27500 | K26: Formatos aplicados | L26: Pendiente | M26: La tasa se ve como 21% y los importes como moneda.
A27: 10 | B27: 46213 | C27: Ana | D27: Impresora | E27: Tecnología | F27: 1 | G27: 255000 | K27: Filtros activos | L27: Pendiente | M27: Aparecen flechas en los encabezados.
A28: 11 | B28: 46214 | C28: Diego | D28: Biblioteca | E28: Oficina | F28: 2 | G28: 96500 | K28: Encabezado inmovilizado | L28: Pendiente | M28: Sigue visible al desplazarse.
A29: 12 | B29: 46215 | C29: Elena | D29: Auriculares | E29: Accesorios | F29: 2 | G29: 53000 | K29: Área de impresión definida | L29: Pendiente | M29: La vista previa incluye toda la tabla.
A30: 13 | B30: 46216 | C30: Ana | D30: Webcam | E30: Tecnología | F30: 2 | G30: 68000
A31: 14 | B31: 46217 | C31: Bruno | D31: Alfombra | E31: Hogar | F31: 1 | G31: 55000

Sheet 08_Soluciones
A1: 8. Soluciones y resultados esperados
A3: Consultá esta hoja después de intentar cada práctica. Las fórmulas se muestran con nombres en español.
A5: 01_Interfaz_Celdas
A6: Práctica | B6: Resultado esperado | C6: Explicación
A7: Serie numérica | B7: 3, 4, 5, 6 | C7: Excel continúa la diferencia constante de 1.
A8: Días | B8: miércoles, jueves, viernes, sábado | C8: Los días están incluidos en las listas automáticas de Excel.
A9: Fechas | B9: 03/07/2026 a 06/07/2026 | C9: Excel suma un día por celda.
A10: Relleno rápido | B10: Carlos / Gómez; Lucía / Pérez; Martín / López; Sofía / Díaz | C10: Ctrl + E completa el patrón de separación.
A12: 02_Copiar_Pegar
A13: Práctica | B13: Resultado | C13: Procedimiento
A14: Aumentar precios 10% | B14: Cuaderno 4.950; Lapicera 1.320; Mochila 31.350; Regla 1.045; Calculadora 19.580 | C14: Copiar 1,10 > seleccionar D30:D34 > Pegado especial > Multiplicar.
A15: Diseño de tabla | B15: Importe en moneda, Margen en porcentaje, Fecha dd/mm/aaaa, bordes y encabezado destacado. | C15: Podés copiar H37:L42 y usar Pegado especial > Formatos sobre A37:E42.
A17: 04_Formulas
A18: Cálculo | B18: Fórmula correcta | C18: Resultado esperado | D18: Resultado calculado
A19: Total de ventas | B19: =SUMA(C23:C29) | C19: 129 | D19: =SUM('04_Formulas'!C23:C29) -> 129
A20: Promedio de visitas | B20: =PROMEDIO(B23:B29) | C20: 146.85714 | D20: =AVERAGE('04_Formulas'!B23:B29) -> 146.85714
A21: Cantidad de días | B21: =CONTAR(C23:C29) | C21: 7 | D21: =COUNT('04_Formulas'!C23:C29) -> 7
A22: Mayor cantidad de ventas | B22: =MAX(C23:C29) | C22: 28 | D22: =MAX('04_Formulas'!C23:C29) -> 28
A23: Menor cantidad de ventas | B23: =MIN(C23:C29) | C23: 11 | D23: =MIN('04_Formulas'!C23:C29) -> 11
A25: 05_Referencias
A26: Celda inicial | B26: Fórmula | C26: Acción | D26: Resultado
A27: C28 | B27: =B28*(1-$B$24) | C27: Presioná Enter y arrastrá hasta C33. | D27: 76500
A28: C29 | B28: =B29*(1-$B$24) | C28: Resultado al copiar | D28: 130500
A29: C30 | B29: =B30*(1-$B$24) | C29: Resultado al copiar | D29: 28800
A30: C31 | B30: =B31*(1-$B$24) | C30: Resultado al copiar | D30: 89100
A31: C32 | B31: =B32*(1-$B$24) | C31: Resultado al copiar | D31: 16650
A32: C33 | B32: =B33*(1-$B$24) | C32: Resultado al copiar | D32: 51300
A34: 07_Practica_Final
A35: Elemento | B35: Fórmula o acción correcta | C35: Resultado / comprobación
A36: Subtotal H18 | B36: =F18*G18 | C36: Copiar hasta H31.
A37: Total con IVA I18 | B37: =H18*(1+$B$15) | C37: Copiar hasta I31; $B$15 no debe cambiar.
A38: Total general | B38: =SUMA(I18:I31)
A39: Promedio de subtotales | B39: =PROMEDIO(H18:H31)
A40: Cantidad de registros | B40: =CONTAR(A18:A31)
A41: Mayor total | B41: =MAX(I18:I31)
A42: Menor total | B42: =MIN(I18:I31)
A43: Filtro pedido | B43: Categoría = Tecnología y Vendedor = Ana | C43: Deben quedar 5 registros.
A45: Resultado final esperado | B45: Fórmula de comprobación | C45: Valor | D45: Interpretación | F45: Fila | G45: Subtotal esperado | H45: Total con IVA esperado
A46: Total general con IVA | B46: =SUMA((Cantidad*Precio)*(1+IVA)) | C46: =SUM(H46:H59) -> 3864740 | D46: Suma de todos los totales. | F46: 18 | G46: ='07_Practica_Final'!F18*'07_Practica_Final'!G18 -> 880000 | H46: =G46*(1+'07_Practica_Final'!$B$15) -> 1064800
A47: Promedio de subtotales | B47: =PROMEDIO(Cantidad*Precio) | C47: =AVERAGE(G46:G59) -> 228142.86 | D47: Promedio antes de IVA. | F47: 19 | G47: ='07_Practica_Final'!F19*'07_Practica_Final'!G19 -> 152000 | H47: =G47*(1+'07_Practica_Final'!$B$15) -> 183920
...
